<?xml version="1.0" ?>
<robot name="Wheel" xmlns:xacro="http://www.ros.org/wiki/xacro">

<xacro:include filename="$(find Wheel_description)/urdf/materials.xacro" />
<xacro:include filename="$(find Wheel_description)/urdf/Wheel.trans" />
<xacro:include filename="$(find Wheel_description)/urdf/Wheel.gazebo" />
<link name="base_link">
  <!-- <inertial>
    <origin xyz="0.06289899283382117 -0.0019999999999999666 0.14200716411697475" rpy="0 0 0"/>
    <mass value="7.853981633974124e-07"/>
    <inertia ixx="0.0" iyy="0.0" izz="0.0" ixy="-0.0" iyz="0.0" ixz="0.0"/>
  </inertial> -->
  <visual>
    <origin xyz="0 0 0" rpy="0 0 0"/>
    <geometry>
      <mesh filename="package://Wheel_description/meshes/base_link.stl" scale="0.001 0.001 0.001"/>
    </geometry>
    <material name="silver"/>
  </visual>
  <collision>
    <origin xyz="0 0 0" rpy="0 0 0"/>
    <geometry>
      <mesh filename="package://Wheel_description/meshes/base_link.stl" scale="0.001 0.001 0.001"/>
    </geometry>
  </collision>
</link>

<link name="body_1">
  <inertial>
    <origin xyz="0.07465305429655415 1.3992316437016344e-08 -0.007171983146712607" rpy="0 0 0"/>
    <mass value="0.7898311199202095"/>
    <inertia ixx="0.000423" iyy="0.001942" izz="0.001911" ixy="-0.0001" iyz="-0.0001" ixz="-0.000246"/>
  </inertial>
  <visual>
    <origin xyz="-0.062899 0.002 -0.141507" rpy="0 0 0"/>
    <geometry>
      <mesh filename="package://Wheel_description/meshes/body_1.stl" scale="0.001 0.001 0.001"/>
    </geometry>
    <material name="silver"/>
  </visual>
  <collision>
    <origin xyz="-0.062899 0.002 -0.141507" rpy="0 0 0"/>
    <geometry>
      <mesh filename="package://Wheel_description/meshes/body_1.stl" scale="0.001 0.001 0.001"/>
    </geometry>
  </collision>
</link>

<link name="back_link_1">
  <inertial>
    <origin xyz="-0.061823091080359494 5.204170427930421e-17 -0.04700897074848197" rpy="0 0 0"/>
    <mass value="0.22030983343093113"/>
    <inertia ixx="0.000264" iyy="0.000599" izz="0.000492" ixy="0.0001" iyz="0.0001" ixz="-0.000247"/>
  </inertial>
  <visual>
    <origin xyz="-0.126692 0.002 -0.129705" rpy="0 0 0"/>
    <geometry>
      <mesh filename="package://Wheel_description/meshes/back_link_1.stl" scale="0.001 0.001 0.001"/>
    </geometry>
    <material name="silver"/>
  </visual>
  <collision>
    <origin xyz="-0.126692 0.002 -0.129705" rpy="0 0 0"/>
    <geometry>
      <mesh filename="package://Wheel_description/meshes/back_link_1.stl" scale="0.001 0.001 0.001"/>
    </geometry>
  </collision>
</link>

<link name="weight_1">
  <inertial>
    <origin xyz="0.03017579116215953 1.8648277366750676e-17 -0.03319374182920071" rpy="0 0 0"/>
    <mass value="0.7950252102829319"/>
    <!-- <mass value="3"/> -->
    <inertia ixx="0.000393" iyy="0.000625" izz="0.000351" ixy="-0.0001" iyz="-0.0001" ixz="0.000224"/>
    <!-- <inertia ixx="0.0016" iyy="0.00245" izz="0.00135" ixy="-0.0001" iyz="-0.0001" ixz="0.0008"/> -->
  </inertial>
  <visual>
    <origin xyz="-0.092285 0.002 -0.098426" rpy="0 0 0"/>
    <geometry>
      <mesh filename="package://Wheel_description/meshes/weight_1.stl" scale="0.001 0.001 0.001"/>
    </geometry>
    <material name="silver"/>
  </visual>
  <collision>
    <origin xyz="-0.092285 0.002 -0.098426" rpy="0 0 0"/>
    <geometry>
      <mesh filename="package://Wheel_description/meshes/weight_1.stl" scale="0.001 0.001 0.001"/>
    </geometry>
  </collision>
</link>

<link name="back_wheel_1">
  <inertial>
    <origin xyz="-7.1662825985863154e-09 0.025000000000000015 -3.6896070457898e-07" rpy="0 0 0"/>
    <mass value="0.3047767327723595"/>
    <inertia ixx="0.000219" iyy="0.000334" izz="0.000219" ixy="0.0001" iyz="0.0001" ixz="0.0"/>
  </inertial>
  <visual>
    <origin xyz="0.017101 0.027 -0.048985" rpy="0 0 0"/>
    <geometry>
      <mesh filename="package://Wheel_description/meshes/back_wheel_1.stl" scale="0.001 0.001 0.001"/>
    </geometry>
    <material name="silver"/>
  </visual>
  <collision>
    <origin xyz="0.017101 0.027 -0.048985" rpy="0 0 0"/>
    <geometry>
      <mesh filename="package://Wheel_description/meshes/back_wheel_1.stl" scale="0.001 0.001 0.001"/>
    </geometry>
    <surface>
      <friction>
        <ode>
          <mu1>100000</mu1>
          <mu2>100000</mu2>
        </ode>
      </friction>
      <!-- <contact>
        <ode>
          <min_depth>0.003</min_depth>
        </ode>
      </contact>       -->
    </surface>
  </collision>
</link>

<link name="front_link_1">
  <inertial>
    <origin xyz="0.010819129030445462 1.0364972768961422e-15 -0.029724615423224784" rpy="0 0 0"/>
    <mass value="0.1290641758429471"/>
    <inertia ixx="0.000398" iyy="0.000316" izz="0.000166" ixy="-0.0001" iyz="-0.0001" ixz="9.7e-05"/>
  </inertial>
  <visual>
    <origin xyz="-0.206629 0.002 -0.14074" rpy="0 0 0"/>
    <geometry>
      <mesh filename="package://Wheel_description/meshes/front_link_1.stl" scale="0.001 0.001 0.001"/>
    </geometry>
    <material name="silver"/>
  </visual>
  <collision>
    <origin xyz="-0.206629 0.002 -0.14074" rpy="0 0 0"/>
    <geometry>
      <mesh filename="package://Wheel_description/meshes/front_link_1.stl" scale="0.001 0.001 0.001"/>
    </geometry>
  </collision>
</link>

<link name="front_wheel_1">
  <inertial>
    <origin xyz="-4.7447299825198463e-07 -0.024579999999999987 -4.958165472218612e-07" rpy="0 0 0"/>
    <mass value="0.29866235409672326"/>
    <inertia ixx="0.000212" iyy="0.000326" izz="0.000212" ixy="-0.0001" iyz="-0.0001" ixz="0.0001"/>
  </inertial>
  <visual>
    <origin xyz="-0.240026 -0.02258 -0.048985" rpy="0 0 0"/>
    <geometry>
      <mesh filename="package://Wheel_description/meshes/front_wheel_1.stl" scale="0.001 0.001 0.001"/>
    </geometry>
    <material name="silver"/>
  </visual>
  <collision>
    <origin xyz="-0.240026 -0.02258 -0.048985" rpy="0 0 0"/>
    <geometry>
      <mesh filename="package://Wheel_description/meshes/front_wheel_1.stl" scale="0.001 0.001 0.001"/>
    </geometry>
    <surface>
      <friction>
        <ode>
          <mu1>100000</mu1>
          <mu2>100000</mu2>
        </ode>
      </friction>
      <!-- <contact>
        <ode>
          <min_depth>0.003</min_depth>
        </ode>
      </contact> -->
    </surface>
  </collision>
</link>

<joint name="base_link" type="fixed">
  <origin xyz="0.062899 -0.002 0.141507" rpy="0 0 0"/>
  <parent link="base_link"/>
  <child link="body_1"/>
</joint>

<joint name="Revolute_2" type="continuous">
  <origin xyz="0.063793 0.0 -0.011802" rpy="0 0 0"/>
  <parent link="body_1"/>
  <child link="back_link_1"/>
  <axis xyz="-0.73994 -0.0 -0.672673"/>
</joint>

<joint name="Rigid_3" type="fixed">
  <origin xyz="-0.034407 0.0 -0.031279" rpy="0 0 0"/>
  <parent link="back_link_1"/>
  <child link="weight_1"/>
</joint>

<joint name="Revolute_4" type="continuous">
  <origin xyz="-0.143793 -0.025 -0.08072" rpy="0 0 0"/>
  <parent link="back_link_1"/>
  <child link="back_wheel_1"/>
  <axis xyz="0.0 -1.0 0.0"/>
</joint>

<joint name="Rigid_5" type="fixed">
  <origin xyz="0.14373 0.0 -0.000767" rpy="0 0 0"/>
  <parent link="body_1"/>
  <child link="front_link_1"/>
  <!-- <axis xyz="0.34202 -0.0 -0.939693"/> -->
</joint>

<joint name="Revolute_6" type="continuous">
  <origin xyz="0.033397 0.02458 -0.091755" rpy="0 0 0"/>
  <parent link="front_link_1"/>
  <child link="front_wheel_1"/>
  <axis xyz="-0.0 1.0 -0.0"/>
</joint>

</robot>
