<?xml version="1.0" ?>
<robot name="motor_0419" xmlns:xacro="http://www.ros.org/wiki/xacro">

<xacro:include filename="$(find motor_0419_description)/urdf/materials.xacro" />
<xacro:include filename="$(find motor_0419_description)/urdf/motor_0419.trans" />
<xacro:include filename="$(find motor_0419_description)/urdf/motor_0419.gazebo" />
<link name="base_link">
  <inertial>
    <origin xyz="-0.2643804540847844 0.0 0.1883280566624717" rpy="0 0 0"/>
    <mass value="7.853981633974392e-07"/>
    <inertia ixx="0.0" iyy="0.0" izz="0.0" ixy="-0.0" iyz="0.0" ixz="0.0"/>
  </inertial>
  <visual>
    <origin xyz="0 0 0" rpy="0 0 0"/>
    <geometry>
      <mesh filename="package://motor_0419_description/meshes/base_link.stl" scale="0.001 0.001 0.001"/>
    </geometry>
    <material name="silver"/>
  </visual>
  <collision>
    <origin xyz="0 0 0" rpy="0 0 0"/>
    <geometry>
      <mesh filename="package://motor_0419_description/meshes/base_link.stl" scale="0.001 0.001 0.001"/>
    </geometry>
  </collision>
</link>

<link name="body_1">
  <inertial>
    <origin xyz="0.1471804534049348 -6.208601174446525e-05 -0.0006579735611396964" rpy="0 0 0"/>
    <mass value="0.8722430217702781"/>
    <inertia ixx="0.000964" iyy="0.006404" izz="0.006542" ixy="-3e-06" iyz="-1e-06" ixz="-0.000829"/>
  </inertial>
  <visual>
    <origin xyz="0.26438 -0.0 -0.187828" rpy="0 0 0"/>
    <geometry>
      <mesh filename="package://motor_0419_description/meshes/body_1.stl" scale="0.001 0.001 0.001"/>
    </geometry>
    <material name="silver"/>
  </visual>
  <collision>
    <origin xyz="0.26438 -0.0 -0.187828" rpy="0 0 0"/>
    <geometry>
      <mesh filename="package://motor_0419_description/meshes/body_1.stl" scale="0.001 0.001 0.001"/>
    </geometry>
  </collision>
</link>

<link name="motor_front_1">
  <inertial>
    <origin xyz="0.002738835734038929 0.0 -0.007526066318017166" rpy="0 0 0"/>
    <mass value="0.14624153072368676"/>
    <inertia ixx="6.7e-05" iyy="6.3e-05" izz="9.1e-05" ixy="0.0" iyz="-0.0" ixz="-1e-05"/>
  </inertial>
  <visual>
    <origin xyz="0.039613 -0.0 -0.168837" rpy="0 0 0"/>
    <geometry>
      <mesh filename="package://motor_0419_description/meshes/motor_front_1.stl" scale="0.001 0.001 0.001"/>
    </geometry>
    <material name="silver"/>
  </visual>
  <collision>
    <origin xyz="0.039613 -0.0 -0.168837" rpy="0 0 0"/>
    <geometry>
      <mesh filename="package://motor_0419_description/meshes/motor_front_1.stl" scale="0.001 0.001 0.001"/>
    </geometry>
  </collision>
</link>

<link name="Component15_1">
  <inertial>
    <origin xyz="0.0047462957723582964 0.0 -0.013040086657548577" rpy="0 0 0"/>
    <mass value="0.06379367109642516"/>
    <inertia ixx="5.1e-05" iyy="8e-06" izz="5.3e-05" ixy="-0.0" iyz="-0.0" ixz="-1e-06"/>
  </inertial>
  <visual>
    <origin xyz="0.030721 -0.0 -0.144405" rpy="0 0 0"/>
    <geometry>
      <mesh filename="package://motor_0419_description/meshes/Component15_1.stl" scale="0.001 0.001 0.001"/>
    </geometry>
    <material name="silver"/>
  </visual>
  <collision>
    <origin xyz="0.030721 -0.0 -0.144405" rpy="0 0 0"/>
    <geometry>
      <mesh filename="package://motor_0419_description/meshes/Component15_1.stl" scale="0.001 0.001 0.001"/>
    </geometry>
  </collision>
</link>

<link name="Component7_1">
  <inertial>
    <origin xyz="0.012826244625287413 0.0 -0.035238526720528365" rpy="0 0 0"/>
    <mass value="0.00441786466911065"/>
    <inertia ixx="2e-06" iyy="2e-06" izz="0.0" ixy="0.0" iyz="-0.0" ixz="1e-06"/>
  </inertial>
  <visual>
    <origin xyz="0.025652 0.038 -0.130477" rpy="0 0 0"/>
    <geometry>
      <mesh filename="package://motor_0419_description/meshes/Component7_1.stl" scale="0.001 0.001 0.001"/>
    </geometry>
    <material name="silver"/>
  </visual>
  <collision>
    <origin xyz="0.025652 0.038 -0.130477" rpy="0 0 0"/>
    <geometry>
      <mesh filename="package://motor_0419_description/meshes/Component7_1.stl" scale="0.001 0.001 0.001"/>
    </geometry>
  </collision>
</link>

<link name="Component8_1">
  <inertial>
    <origin xyz="0.012826244625287411 -4.85722573273506e-17 -0.03523852672052845" rpy="0 0 0"/>
    <mass value="0.004417864669110651"/>
    <inertia ixx="2e-06" iyy="2e-06" izz="0.0" ixy="0.0" iyz="-0.0" ixz="1e-06"/>
  </inertial>
  <visual>
    <origin xyz="0.025652 -0.038 -0.130477" rpy="0 0 0"/>
    <geometry>
      <mesh filename="package://motor_0419_description/meshes/Component8_1.stl" scale="0.001 0.001 0.001"/>
    </geometry>
    <material name="silver"/>
  </visual>
  <collision>
    <origin xyz="0.025652 -0.038 -0.130477" rpy="0 0 0"/>
    <geometry>
      <mesh filename="package://motor_0419_description/meshes/Component8_1.stl" scale="0.001 0.001 0.001"/>
    </geometry>
  </collision>
</link>

<link name="Component21_1">
  <inertial>
    <origin xyz="0.0005748724370470565 6.938893903907228e-18 -0.001579449039853624" rpy="0 0 0"/>
    <mass value="0.04065244111471174"/>
    <inertia ixx="1e-05" iyy="1.9e-05" izz="1.1e-05" ixy="-0.0" iyz="0.0" ixz="-0.0"/>
  </inertial>
  <visual>
    <origin xyz="-0.0 0.038 -0.06" rpy="0 0 0"/>
    <geometry>
      <mesh filename="package://motor_0419_description/meshes/Component21_1.stl" scale="0.001 0.001 0.001"/>
    </geometry>
    <material name="silver"/>
  </visual>
  <collision>
    <origin xyz="-0.0 0.038 -0.06" rpy="0 0 0"/>
    <geometry>
      <mesh filename="package://motor_0419_description/meshes/Component21_1.stl" scale="0.001 0.001 0.001"/>
    </geometry>
  </collision>
</link>

<link name="Component22_1">
  <inertial>
    <origin xyz="0.0005748724370470528 0.0 -0.001579449039853617" rpy="0 0 0"/>
    <mass value="0.040652441114711745"/>
    <inertia ixx="1e-05" iyy="1.9e-05" izz="1.1e-05" ixy="-0.0" iyz="0.0" ixz="-0.0"/>
  </inertial>
  <visual>
    <origin xyz="-0.0 -0.038 -0.06" rpy="0 0 0"/>
    <geometry>
      <mesh filename="package://motor_0419_description/meshes/Component22_1.stl" scale="0.001 0.001 0.001"/>
    </geometry>
    <material name="silver"/>
  </visual>
  <collision>
    <origin xyz="-0.0 -0.038 -0.06" rpy="0 0 0"/>
    <geometry>
      <mesh filename="package://motor_0419_description/meshes/Component22_1.stl" scale="0.001 0.001 0.001"/>
    </geometry>
  </collision>
</link>

<link name="front_wheel_1">
  <inertial>
    <origin xyz="8.769646358161552e-18 -0.03 2.0816681711721685e-17" rpy="0 0 0"/>
    <mass value="0.5185469656518696"/>
    <inertia ixx="0.000506" iyy="0.000784" izz="0.000506" ixy="0.0" iyz="0.0" ixz="0.0"/>
  </inertial>
  <visual>
    <origin xyz="-0.0 -0.03 -0.06" rpy="0 0 0"/>
    <geometry>
      <mesh filename="package://motor_0419_description/meshes/front_wheel_1.stl" scale="0.001 0.001 0.001"/>
    </geometry>
    <material name="silver"/>
  </visual>
  <collision>
    <origin xyz="-0.0 -0.03 -0.06" rpy="0 0 0"/>
    <geometry>
      <mesh filename="package://motor_0419_description/meshes/front_wheel_1.stl" scale="0.001 0.001 0.001"/>
    </geometry>
  </collision>
</link>

<link name="weight_shell_1">
  <inertial>
    <origin xyz="-0.018334899960794432 0.041546025220520574 -0.001470528410080843" rpy="0 0 0"/>
    <mass value="0.07612453425279354"/>
    <inertia ixx="5.9e-05" iyy="4.2e-05" izz="5.5e-05" ixy="0.0" iyz="-0.0" ixz="-1.2e-05"/>
  </inertial>
  <visual>
    <origin xyz="0.138424 0.041546 -0.119052" rpy="0 0 0"/>
    <geometry>
      <mesh filename="package://motor_0419_description/meshes/weight_shell_1.stl" scale="0.001 0.001 0.001"/>
    </geometry>
    <material name="silver"/>
  </visual>
  <collision>
    <origin xyz="0.138424 0.041546 -0.119052" rpy="0 0 0"/>
    <geometry>
      <mesh filename="package://motor_0419_description/meshes/weight_shell_1.stl" scale="0.001 0.001 0.001"/>
    </geometry>
  </collision>
</link>

<link name="motor_back_1">
  <inertial>
    <origin xyz="0.012633058157315635 7.77390917334006e-18 0.010600574126347323" rpy="0 0 0"/>
    <mass value="0.1462415307236867"/>
    <inertia ixx="8.2e-05" iyy="6.3e-05" izz="7.6e-05" ixy="0.0" iyz="-0.0" ixz="1.6e-05"/>
  </inertial>
  <visual>
    <origin xyz="0.115865 -0.0 -0.127171" rpy="0 0 0"/>
    <geometry>
      <mesh filename="package://motor_0419_description/meshes/motor_back_1.stl" scale="0.001 0.001 0.001"/>
    </geometry>
    <material name="silver"/>
  </visual>
  <collision>
    <origin xyz="0.115865 -0.0 -0.127171" rpy="0 0 0"/>
    <geometry>
      <mesh filename="package://motor_0419_description/meshes/motor_back_1.stl" scale="0.001 0.001 0.001"/>
    </geometry>
  </collision>
</link>

<link name="weight_1">
  <inertial>
    <origin xyz="-0.0005088231683351985 1.830746664977666e-18 -0.057373356889244886" rpy="0 0 0"/>
    <mass value="0.1552465448885618"/>
    <inertia ixx="0.00012" iyy="0.000154" izz="6.1e-05" ixy="0.0" iyz="0.0" ixz="1.8e-05"/>
  </inertial>
  <visual>
    <origin xyz="0.117014 -0.0 -0.126207" rpy="0 0 0"/>
    <geometry>
      <mesh filename="package://motor_0419_description/meshes/weight_1.stl" scale="0.001 0.001 0.001"/>
    </geometry>
    <material name="silver"/>
  </visual>
  <collision>
    <origin xyz="0.117014 -0.0 -0.126207" rpy="0 0 0"/>
    <geometry>
      <mesh filename="package://motor_0419_description/meshes/weight_1.stl" scale="0.001 0.001 0.001"/>
    </geometry>
  </collision>
</link>

<link name="bone_1">
  <inertial>
    <origin xyz="-0.0032816521132274235 0.0 0.015670028427721583" rpy="0 0 0"/>
    <mass value="0.013027262224009139"/>
    <inertia ixx="5e-06" iyy="1e-05" izz="6e-06" ixy="0.0" iyz="-0.0" ixz="-4e-06"/>
  </inertial>
  <visual>
    <origin xyz="0.150498 -0.0 -0.079659" rpy="0 0 0"/>
    <geometry>
      <mesh filename="package://motor_0419_description/meshes/bone_1.stl" scale="0.001 0.001 0.001"/>
    </geometry>
    <material name="silver"/>
  </visual>
  <collision>
    <origin xyz="0.150498 -0.0 -0.079659" rpy="0 0 0"/>
    <geometry>
      <mesh filename="package://motor_0419_description/meshes/bone_1.stl" scale="0.001 0.001 0.001"/>
    </geometry>
  </collision>
</link>

<link name="Component13_1">
  <inertial>
    <origin xyz="-0.004854721414989244 -5.274585027369104e-10 0.0029938954157708447" rpy="0 0 0"/>
    <mass value="0.17819280824555334"/>
    <inertia ixx="0.000182" iyy="6.2e-05" izz="0.000164" ixy="-0.0" iyz="0.0" ixz="-4e-06"/>
  </inertial>
  <visual>
    <origin xyz="0.188256 -0.0 -0.066428" rpy="0 0 0"/>
    <geometry>
      <mesh filename="package://motor_0419_description/meshes/Component13_1.stl" scale="0.001 0.001 0.001"/>
    </geometry>
    <material name="silver"/>
  </visual>
  <collision>
    <origin xyz="0.188256 -0.0 -0.066428" rpy="0 0 0"/>
    <geometry>
      <mesh filename="package://motor_0419_description/meshes/Component13_1.stl" scale="0.001 0.001 0.001"/>
    </geometry>
  </collision>
</link>

<link name="Component4_1">
  <inertial>
    <origin xyz="-0.030000494709475384 -2.7755575615628914e-17 2.7755575615628914e-17" rpy="0 0 0"/>
    <mass value="0.0035342917352885143"/>
    <inertia ixx="0.0" iyy="1e-06" izz="1e-06" ixy="0.0" iyz="0.0" ixz="0.0"/>
  </inertial>
  <visual>
    <origin xyz="0.202916 0.038 -0.06" rpy="0 0 0"/>
    <geometry>
      <mesh filename="package://motor_0419_description/meshes/Component4_1.stl" scale="0.001 0.001 0.001"/>
    </geometry>
    <material name="silver"/>
  </visual>
  <collision>
    <origin xyz="0.202916 0.038 -0.06" rpy="0 0 0"/>
    <geometry>
      <mesh filename="package://motor_0419_description/meshes/Component4_1.stl" scale="0.001 0.001 0.001"/>
    </geometry>
  </collision>
</link>

<link name="Component3_1">
  <inertial>
    <origin xyz="-0.030000494709475717 4.163336342344337e-17 1.249000902703301e-16" rpy="0 0 0"/>
    <mass value="0.0035342917352885125"/>
    <inertia ixx="0.0" iyy="1e-06" izz="1e-06" ixy="-0.0" iyz="0.0" ixz="-0.0"/>
  </inertial>
  <visual>
    <origin xyz="0.202916 -0.038 -0.06" rpy="0 0 0"/>
    <geometry>
      <mesh filename="package://motor_0419_description/meshes/Component3_1.stl" scale="0.001 0.001 0.001"/>
    </geometry>
    <material name="silver"/>
  </visual>
  <collision>
    <origin xyz="0.202916 -0.038 -0.06" rpy="0 0 0"/>
    <geometry>
      <mesh filename="package://motor_0419_description/meshes/Component3_1.stl" scale="0.001 0.001 0.001"/>
    </geometry>
  </collision>
</link>

<link name="Component12_1">
  <inertial>
    <origin xyz="-0.018143698328590363 -6.938893903907228e-18 3.364669654004615e-14" rpy="0 0 0"/>
    <mass value="0.04328224157161273"/>
    <inertia ixx="1.1e-05" iyy="1.9e-05" izz="1e-05" ixy="0.0" iyz="-0.0" ixz="-0.0"/>
  </inertial>
  <visual>
    <origin xyz="0.262916 -0.038 -0.06" rpy="0 0 0"/>
    <geometry>
      <mesh filename="package://motor_0419_description/meshes/Component12_1.stl" scale="0.001 0.001 0.001"/>
    </geometry>
    <material name="silver"/>
  </visual>
  <collision>
    <origin xyz="0.262916 -0.038 -0.06" rpy="0 0 0"/>
    <geometry>
      <mesh filename="package://motor_0419_description/meshes/Component12_1.stl" scale="0.001 0.001 0.001"/>
    </geometry>
  </collision>
</link>

<link name="Component11_1">
  <inertial>
    <origin xyz="-0.018143698328590363 6.938893903907228e-18 3.364669654004615e-14" rpy="0 0 0"/>
    <mass value="0.04328224157161273"/>
    <inertia ixx="1.1e-05" iyy="1.9e-05" izz="1e-05" ixy="-0.0" iyz="0.0" ixz="-0.0"/>
  </inertial>
  <visual>
    <origin xyz="0.262916 0.038 -0.06" rpy="0 0 0"/>
    <geometry>
      <mesh filename="package://motor_0419_description/meshes/Component11_1.stl" scale="0.001 0.001 0.001"/>
    </geometry>
    <material name="silver"/>
  </visual>
  <collision>
    <origin xyz="0.262916 0.038 -0.06" rpy="0 0 0"/>
    <geometry>
      <mesh filename="package://motor_0419_description/meshes/Component11_1.stl" scale="0.001 0.001 0.001"/>
    </geometry>
  </collision>
</link>

<link name="back_wheel_1">
  <inertial>
    <origin xyz="0.0 0.03 1.3877787807814457e-17" rpy="0 0 0"/>
    <mass value="0.5185469656518696"/>
    <inertia ixx="0.000506" iyy="0.000784" izz="0.000506" ixy="0.0" iyz="0.0" ixz="-0.0"/>
  </inertial>
  <visual>
    <origin xyz="0.28 0.03 -0.06" rpy="0 0 0"/>
    <geometry>
      <mesh filename="package://motor_0419_description/meshes/back_wheel_1.stl" scale="0.001 0.001 0.001"/>
    </geometry>
    <material name="silver"/>
  </visual>
  <collision>
    <origin xyz="0.28 0.03 -0.06" rpy="0 0 0"/>
    <geometry>
      <mesh filename="package://motor_0419_description/meshes/back_wheel_1.stl" scale="0.001 0.001 0.001"/>
    </geometry>
  </collision>
</link>

<joint name="base" type="fixed">
  <origin xyz="-0.26438 0.0 0.187828" rpy="0 0 0"/>
  <parent link="base_link"/>
  <child link="body_1"/>
</joint>

<joint name="Rigid 2" type="fixed">
  <origin xyz="0.224767 0.0 -0.018991" rpy="0 0 0"/>
  <parent link="body_1"/>
  <child link="motor_front_1"/>
</joint>

<joint name="front_fork" type="continuous">
  <origin xyz="0.008892 0.0 -0.024432" rpy="0 0 0"/>
  <parent link="motor_front_1"/>
  <child link="Component15_1"/>
  <axis xyz="-0.34202 0.0 0.939693"/>
</joint>

<joint name="Rigid 4" type="fixed">
  <origin xyz="0.005069 -0.038 -0.013928" rpy="0 0 0"/>
  <parent link="Component15_1"/>
  <child link="Component7_1"/>
</joint>

<joint name="Rigid 5" type="fixed">
  <origin xyz="0.005069 0.038 -0.013928" rpy="0 0 0"/>
  <parent link="Component15_1"/>
  <child link="Component8_1"/>
</joint>

<joint name="Rigid 6" type="fixed">
  <origin xyz="0.025652 0.0 -0.070477" rpy="0 0 0"/>
  <parent link="Component7_1"/>
  <child link="Component21_1"/>
</joint>

<joint name="Rigid 7" type="fixed">
  <origin xyz="0.025652 0.0 -0.070477" rpy="0 0 0"/>
  <parent link="Component8_1"/>
  <child link="Component22_1"/>
</joint>

<joint name="front_wh" type="continuous">
  <origin xyz="0.0 -0.008 0.0" rpy="0 0 0"/>
  <parent link="Component22_1"/>
  <child link="front_wheel_1"/>
  <axis xyz="0.0 -1.0 0.0"/>
</joint>

<joint name="Rigid 9" type="fixed">
  <origin xyz="0.125956 -0.041546 -0.068776" rpy="0 0 0"/>
  <parent link="body_1"/>
  <child link="weight_shell_1"/>
</joint>

<joint name="Rigid 10" type="fixed">
  <origin xyz="0.022559 0.041546 0.008119" rpy="0 0 0"/>
  <parent link="weight_shell_1"/>
  <child link="motor_back_1"/>
</joint>

<joint name="back_fork" type="revolute">
  <origin xyz="-0.001149 0.0 -0.000964" rpy="0 0 0"/>
  <parent link="motor_back_1"/>
  <child link="weight_1"/>
  <axis xyz="-0.766044 0.0 -0.642788"/>
  <limit upper="1.047198" lower="-1.047198" effort="100" velocity="100"/>
</joint>

<joint name="Rigid 12" type="fixed">
  <origin xyz="-0.033484 0.0 -0.046548" rpy="0 0 0"/>
  <parent link="weight_1"/>
  <child link="bone_1"/>
</joint>

<joint name="Rigid 13" type="fixed">
  <origin xyz="-0.037758 0.0 -0.013231" rpy="0 0 0"/>
  <parent link="bone_1"/>
  <child link="Component13_1"/>
</joint>

<joint name="Rigid 14" type="fixed">
  <origin xyz="-0.01466 -0.038 -0.006428" rpy="0 0 0"/>
  <parent link="Component13_1"/>
  <child link="Component4_1"/>
</joint>

<joint name="Rigid 15" type="fixed">
  <origin xyz="-0.01466 0.038 -0.006428" rpy="0 0 0"/>
  <parent link="Component13_1"/>
  <child link="Component3_1"/>
</joint>

<joint name="Rigid 16" type="fixed">
  <origin xyz="-0.06 0.0 0.0" rpy="0 0 0"/>
  <parent link="Component3_1"/>
  <child link="Component12_1"/>
</joint>

<joint name="Rigid 17" type="fixed">
  <origin xyz="-0.06 0.0 0.0" rpy="0 0 0"/>
  <parent link="Component4_1"/>
  <child link="Component11_1"/>
</joint>

<joint name="back_wh" type="continuous">
  <origin xyz="-0.017084 0.008 0.0" rpy="0 0 0"/>
  <parent link="Component11_1"/>
  <child link="back_wheel_1"/>
  <axis xyz="0.0 -1.0 0.0"/>
</joint>

</robot>
